Workbook

Sheet Table 1
A1: Table 1. IDA Country Allocations in FY25
A2: (SDR million)
D4: FY25 | I4: FY25 | N4: FY24 | S4: FY25 | X4: FY25
A5: National IDA Allocations | D5: Allocations (before FY25 set-asides and reallocations and FY24 front-/back- loading) a/ (I) | I5: Set-aside Adjustments b/ (II) | N5: FY24 Front/Back Loading c/ (III) | S5: FY25 Reallocations (IV) | X5: Final Allocations (after FY25 set-asides and reallocations and FY24 front-/back- loading) d/ (V=I+II+III+IV)
A6: Country | D6: Grants | E6: Credits | F6: PBA-SMLs e/ | G6: Total | I6: Grants | J6: Credits | K6: PBA-SMLs e/ | L6: Total | N6: Grants | O6: Credits | P6: PBA-SMLs e/ | Q6: Total | S6: Grants | T6: Credits | U6: PBA-SMLs e/ | V6: Total | X6: Grants | Y6: Credits | Z6: PBA-SMLs e/ | AA6: Total
A7: Africa Eastern and Southern
A8: Burundi | B8: f/ | D8: 183.14803 | E8: 0.0 | F8: 0 | G8: 183.14803 | I8: 0 | J8: 0 | K8: 0 | L8: 0 | N8: -6.7370498 | O8: 0 | P8: 0 | Q8: -6.7370498 | S8: 81.20278 | T8: 0 | U8: 0 | V8: 81.20278 | X8: 257.61376 | Y8: 0 | Z8: 0 | AA8: 257.61376 | AB8: =AA8/G8*100-100 -> 40.658766
A9: Comoros | D9: 18.149145 | E9: 0.0 | F9: 0 | G9: 18.149145 | I9: 0 | J9: 0 | K9: 0 | L9: 0 | N9: -14.231026 | O9: 0 | P9: 0 | Q9: -14.231026 | S9: 0 | T9: 0 | U9: 0 | V9: 0 | X9: 3.9181185 | Y9: 0 | Z9: 0 | AA9: 3.9181185 | AB9: =AA9/G9*100-100 -> -78.411553
A10: Congo, Democratic Republic of | D10: 0 | E10: 657.23989 | F10: 75.173608 | G10: 732.41349 | I10: 0 | J10: 0 | K10: 0 | L10: 0 | N10: 0 | O10: -307.61257 | P10: 218.17171 | Q10: -89.440857 | S10: 0 | T10: -21.272352 | U10: -2.4330834 | V10: -23.705436 | X10: 0 | Y10: 328.35497 | Z10: 290.91223 | AA10: 619.2672 | AB10: =AA10/G10*100-100 -> -15.448417
A11: Eritrea | B11: i/ | D11: 0 | E11: 0.0 | F11: 0 | G11: 0 | I11: 0 | J11: 0 | K11: 0 | L11: 0 | N11: 0 | O11: 0 | P11: 0 | Q11: 0 | S11: 0 | T11: 0 | U11: 0 | V11: 0 | X11: 0 | Y11: 0 | Z11: 0 | AA11: 0 | AB11: =AA11/G11*100-100 -> #DIV/0!
A12: Eswatini | B12: j/ | D12: 0.0 | E12: 20.795188 | F12: 0 | G12: 20.795188 | I12: 0 | J12: 0 | K12: 0 | L12: 0 | N12: 0 | O12: 0 | P12: 0 | Q12: 0 | S12: 0 | T12: 10.402505 | U12: 0 | V12: 10.402505 | X12: 0 | Y12: 31.197693 | Z12: 0 | AA12: 31.197693 | AB12: =AA12/G12*100-100 -> 50.023617
A13: Ethiopia | B13: h/ | D13: 699.6236 | E13: 469.68986 | F13: 0 | G13: 1169.3135 | I13: 0 | J13: 0 | K13: 0 | L13: 0 | N13: 10.45475 | O13: -15.400314 | P13: 0 | Q13: -4.9455641 | S13: 31.620612 | T13: 0 | U13: 0 | V13: 31.620612 | X13: 741.69896 | Y13: 454.28954 | Z13: 0 | AA13: 1195.9885 | AB13: =AA13/G13*100-100 -> 2.2812572
A14: Kenya | D14: 0.0 | E14: 555.89735 | F14: 143.5878 | G14: 699.48515 | I14: 0 | J14: 0 | K14: 0 | L14: 0 | N14: 0 | O14: -432.55617 | P14: -116.58897 | Q14: -549.14514 | S14: 0 | T14: 78.677635 | U14: 20.322365 | V14: 99 | X14: 0 | Y14: 202.01882 | Z14: 47.321201 | AA14: 249.34002 | AB14: =AA14/G14*100-100 -> -64.35378
A15: Lesotho | B15: g/, b/ | D15: 0.0 | E15: 26.312616 | F15: 6.7965258 | G15: 33.109141 | I15: 0 | J15: 0 | K15: -3.3109141 | L15: -3.3109141 | N15: 0 | O15: -8.9137076 | P15: 1.2821542 | Q15: -7.6315534 | S15: 0 | T15: 0 | U15: 0 | V15: 0 | X15: 0 | Y15: 17.398908 | Z15: 4.7677659 | AA15: 22.166674 | AB15: =AA15/G15*100-100 -> -33.049687
A16: Madagascar | D16: 0.0 | E16: 227.50616 | F16: 26.021639 | G16: 253.5278 | I16: 0 | J16: 0 | K16: 0 | L16: 0 | N16: 0 | O16: -88.456109 | P16: 59.288622 | Q16: -29.167487 | S16: 0 | T16: 13.030071 | U16: 1.4903499 | V16: 14.520421 | X16: 0 | Y16: 152.08013 | Z16: 86.800611 | AA16: 238.88074 | AB16: =AA16/G16*100-100 -> -5.7773018
A17: Malawi | D17: 194.18356 | E17: 0.0 | F17: 0 | G17: 194.18356 | I17: 0 | J17: 0 | K17: 0 | L17: 0 | N17: -179.20473 | O17: 0 | P17: 0 | Q17: -179.20473 | S17: 239.40412 | T17: 0 | U17: 0 | V17: 239.40412 | X17: 254.38294 | Y17: 0 | Z17: 0 | AA17: 254.38294 | AB17: =AA17/G17*100-100 -> 31.001276
A18: Mozambique | B18: f/ | D18: 456.64325 | E18: 0.0 | F18: 0 | G18: 456.64325 | I18: 0 | J18: 0 | K18: 0 | L18: 0 | N18: -68.460515 | O18: -222.5 | P18: 0 | Q18: -290.96052 | S18: 111.6 | T18: 0 | U18: 0 | V18: 111.6 | X18: 499.78273 | Y18: -222.5 | Z18: 0 | AA18: 277.28273 | AB18: =AA18/G18*100-100 -> -39.278039
A19: Rwanda | D19: 0.0 | E19: 234.74258 | F19: 26.849324 | G19: 261.59191 | I19: 0 | J19: 0 | K19: 0 | L19: 0 | N19: 0 | O19: -125.65573 | P19: -15.888758 | Q19: -141.54448 | S19: 0 | T19: 104.48002 | U19: 11.950188 | V19: 116.43021 | X19: 0 | Y19: 213.56688 | Z19: 22.910755 | AA19: 236.47764 | AB19: =AA19/G19*100-100 -> -9.6005543
A20: Sao Tome and Principe | B20: b/ | D20: 16.623402 | E20: 0.0 | F20: 0 | G20: 16.623402 | I20: 4.1647213 | J20: 0 | K20: 0 | L20: 4.1647213 | N20: -8.4882068 | O20: 0 | P20: 0 | Q20: -8.4882068 | S20: 18.2 | T20: 0 | U20: 0 | V20: 18.2 | X20: 30.499917 | Y20: 0 | Z20: 0 | AA20: 30.499917 | AB20: =AA20/G20*100-100 -> 83.47578
A21: Somalia | B21: f/, k/ | D21: 227.73791 | E21: 0.0 | F21: 0 | G21: 227.73791 | I21: 0 | J21: 0 | K21: 0 | L21: 0 | N21: 20.242884 | O21: 0 | P21: 0 | Q21: 20.242884 | S21: -2.3 | T21: 0 | U21: 0 | V21: -2.3 | X21: 245.6808 | Y21: 0 | Z21: 0 | AA21: 245.6808 | AB21: =AA21/G21*100-100 -> 7.8787427
A22: South Sudan | B22: f/ | D22: 71.482788 | E22: 0.0 | F22: 0 | G22: 71.482788 | I22: 0 | J22: 0 | K22: 0 | L22: 0 | N22: 12.008216 | O22: 0 | P22: 0 | Q22: 12.008216 | S22: -2.6 | T22: 0 | U22: 0 | V22: -2.6 | X22: 80.891003 | Y22: 0 | Z22: 0 | AA22: 80.891003 | AB22: =AA22/G22*100-100 -> 13.161512
A23: Sudan | D23: 131.91835 | E23: 0.0 | F23: 0 | G23: 131.91835 | I23: 0 | J23: 0 | K23: 0 | L23: 0 | N23: -3.054738e-13 | O23: 0 | P23: 0 | Q23: -3.054738e-13 | S23: 0 | T23: 0 | U23: 0 | V23: 0 | X23: 131.91835 | Y23: 0 | Z23: 0 | AA23: 131.91835 | AB23: =AA23/G23*100-100 -> -2.2737368e-13
A24: Tanzania | D24: 0.0 | E24: 582.16798 | F24: 66.587054 | G24: 648.75504 | I24: 0 | J24: 0 | K24: 0 | L24: 0 | N24: 0 | O24: -368.85181 | P24: 144.63926 | Q24: -224.21255 | S24: 0 | T24: 124.13 | U24: 14.197708 | V24: 138.3277 | X24: 0 | Y24: 337.44617 | Z24: 225.42403 | AA24: 562.87019 | AB24: =AA24/G24*100-100 -> -13.238409
A25: Uganda | B25: b/ | D25: 0.0 | E25: 485.77218 | F25: 55.561521 | G25: 541.3337 | I25: 0 | J25: 0 | K25: -54.13337 | L25: -54.13337 | N25: 0 | O25: 282.35724 | P25: 19.499822 | Q25: 301.85706 | S25: 0 | T25: -379.87314 | U25: -40.767896 | V25: -420.64103 | X25: 0 | Y25: 388.25629 | Z25: -19.839923 | AA25: 368.41636 | AB25: =AA25/G25*100-100 -> -31.942837
A26: Zambia | D26: 177.33253 | E26: 0.0 | F26: 0 | G26: 177.33253 | I26: 0 | J26: 0 | K26: 0 | L26: 0 | N26: -134.08694 | O26: 0 | P26: 0 | Q26: -134.08694 | S26: 107.74023 | T26: 0 | U26: 0 | V26: 107.74023 | X26: 150.98582 | Y26: 0 | Z26: 0 | AA26: 150.98582 | AB26: =AA26/G26*100-100 -> -14.857234
A27: Zimbabwe | B27: i/ | D27: 0 | E27: 0 | F27: 0 | G27: 0 | I27: 0 | J27: 0 | K27: 0 | L27: 0 | N27: 0 | O27: 0 | P27: 0 | Q27: 0 | S27: 0 | T27: 0 | U27: 0 | V27: 0 | X27: 0 | Y27: 0 | Z27: 0 | AA27: 0 | AB27: =AA27/G27*100-100 -> #DIV/0!
A28: Subtotal | D28: 2176.8426 | E28: 3260.1238 | F28: 400.57747 | G28: 5837.5439 | I28: 4.1647213 | J28: 0 | K28: -57.444285 | L28: -53.279563 | N28: -368.50262 | O28: -1287.5892 | P28: 310.40385 | Q28: -1345.6879 | S28: 584.86774 | T28: -70.425259 | U28: 4.7596313 | V28: 519.20211 | X28: 2397.3724 | Y28: 1902.1094 | Z28: 658.29667 | AA28: 4957.7785 | AB28: =AA28/G28*100-100 -> -15.070814
A29: Africa Western and Central | AB29: =AA29/G29*100-100 -> #DIV/0!
A30: Benin | B30: f/, g/ | D30: 0.0 | E30: 303.46315 | F30: 78.384267 | G30: 381.84741 | I30: 0 | J30: 0 | K30: 0 | L30: 0 | N30: 0 | O30: -30.242666 | P30: 29.354736 | Q30: -0.88792984 | S30: 0 | T30: 0 | U30: 0 | V30: 0 | X30: 0 | Y30: 273.22048 | Z30: 107.739 | AA30: 380.95948 | AB30: =AA30/G30*100-100 -> -0.23253525
A31: Burkina Faso | D31: 0 | E31: 231.44348 | F31: 26.47198 | G31: 257.91546 | I31: 0 | J31: 0 | K31: 0 | L31: 0 | N31: 0 | O31: -5.3582395 | P31: 100.8197 | Q31: 95.46146 | S31: 0 | T31: 0 | U31: 0 | V31: 0 | X31: 0 | Y31: 226.08524 | Z31: 127.29168 | AA31: 353.37692 | AB31: =AA31/G31*100-100 -> 37.012695
A32: Cameroon | D32: 0 | E32: 194.77278 | F32: 50.309641 | G32: 245.08242 | I32: 0 | J32: 0 | K32: 0 | L32: 0 | N32: 0 | O32: -37.547181 | P32: 127.69077 | Q32: 90.143589 | S32: 0 | T32: 0 | U32: 0 | V32: 0 | X32: 0 | Y32: 157.2256 | Z32: 178.00041 | AA32: 335.22601 | AB32: =AA32/G32*100-100 -> 36.780927
A33: Cape Verde | D33: 0.0 | E33: 18.753049 | F33: 4.8438962 | G33: 23.596945 | I33: 0 | J33: 0 | K33: 0 | L33: 0 | N33: 0 | O33: -24.533461 | P33: 6.3260726 | Q33: -18.207388 | S33: 0 | T33: 14.762974 | U33: 2.7080943 | V33: 17.471069 | X33: 0 | Y33: 8.9825619 | Z33: 13.878063 | AA33: 22.860625 | AB33: =AA33/G33*100-100 -> -3.1204027
A34: Central African Republic | D34: 46.322678 | E34: 0 | F34: 0 | G34: 46.322678 | I34: 0 | J34: 0 | K34: 0 | L34: 0 | N34: -18.991229 | O34: 0 | P34: 0 | Q34: -18.991229 | S34: 48.298218 | T34: 0 | U34: 0 | V34: 48.298218 | X34: 75.629667 | Y34: 0 | Z34: 0 | AA34: 75.629667 | AB34: =AA34/G34*100-100 -> 63.267043
A35: Chad | B35: f/ | D35: 157.20933 | E35: 0 | F35: 0 | G35: 157.20933 | I35: 0 | J35: 0 | K35: 0 | L35: 0 | N35: -28.348168 | O35: 0 | P35: 0 | Q35: -28.348168 | S35: 95.110337 | T35: 0 | U35: 0 | V35: 95.110337 | X35: 223.9715 | Y35: 0 | Z35: 0 | AA35: 223.9715 | AB35: =AA35/G35*100-100 -> 42.467054
A36: Congo, Republic of | D36: 0.0 | E36: 40.228183 | F36: 10.390905 | G36: 50.619087 | I36: 0 | J36: 0 | K36: 0 | L36: 0 | N36: 0 | O36: -41.453433 | P36: 1.1007482 | Q36: -40.352685 | S36: 0 | T36: 0 | U36: 0 | V36: 0 | X36: 0 | Y36: -1.2252504 | Z36: 11.491653 | AA36: 10.266402 | AB36: =AA36/G36*100-100 -> -79.718318
A37: Cote d'Ivoire | B37: g/ | D37: 0.0 | E37: 310.30557 | F37: 80.151659 | G37: 390.45723 | I37: 0 | J37: 0 | K37: 0 | L37: 0 | N37: 0 | O37: -144.72877 | P37: -55.071915 | Q37: -199.80068 | S37: 0 | T37: 9.6776624 | U37: 2.4997318 | V37: 12.177394 | X37: 0 | Y37: 175.25446 | Z37: 27.579476 | AA37: 202.83394 | AB37: =AA37/G37*100-100 -> -48.0522
A38: Gambia, The | B38: f/ | D38: 90.424686 | E38: 0.0 | F38: 0 | G38: 90.424686 | I38: 0 | J38: 0 | K38: 0 | L38: 0 | N38: -47.706077 | O38: 0 | P38: 0 | Q38: -47.706077 | S38: 39.381624 | T38: 0 | U38: 0 | V38: 39.381624 | X38: 82.100233 | Y38: 0 | Z38: 0 | AA38: 82.100233 | AB38: =AA38/G38*100-100 -> -9.2059518
A39: Ghana | B39: g/ | D39: 0.0 | E39: 318.74445 | F39: 82.331416 | G39: 401.07587 | I39: 0 | J39: 0 | K39: 0 | L39: 0 | N39: 0 | O39: -54.034087 | P39: -64.379743 | Q39: -118.41383 | S39: 0 | T39: 0 | U39: 0 | V39: 0 | X39: 0 | Y39: 264.71037 | Z39: 17.951673 | AA39: 282.66204 | AB39: =AA39/G39*100-100 -> -29.524047
A40: Guinea | D40: 0.0 | E40: 116.35745 | F40: 13.308701 | G40: 129.66615 | I40: 0 | J40: 0 | K40: 0 | L40: 0 | N40: 0 | O40: 68.684792 | P40: 31.962164 | Q40: 100.64696 | S40: 0 | T40: -10.927528 | U40: -1.2498659 | V40: -12.177394 | X40: 0 | Y40: 174.11471 | Z40: 44.020999 | AA40: 218.13571 | AB40: =AA40/G40*100-100 -> 68.228727
A41: Guinea-Bissau | D41: 23.203898 | E41: 0.0 | F41: 0 | G41: 23.203898 | I41: 0 | J41: 0 | K41: 0 | L41: 0 | N41: 6.1000247 | O41: 0 | P41: 0 | Q41: 6.1000247 | S41: 0 | T41: 0 | U41: 0 | V41: 0 | X41: 29.303923 | Y41: 0 | Z41: 0 | AA41: 29.303923 | AB41: =AA41/G41*100-100 -> 26.288793
...

Sheet Sheet1

Sheet Table 2
B1: Table 2. Key Input Data for FY25 Allocations | F1: =CORREL(F7:F90,$O$7:$O$90) -> 0.11830706 | G1: =CORREL(G7:G90,$O$7:$O$90) -> 0.90809968 | H1: =CORREL(H7:H90,$O$7:$O$90) -> -0.28543817
B3: Country | C3: 2023
C4: Average of CPIA Clusters A, B & C | D4: CPIA Cluster D | E4: Portfolio Performance Rating (PPR) | F4: Country Performance Rating (CPR) | G4: Population (million) | H4: GNI per Capita (US$)
B6: Africa Eastern and Southern
A7: BJ | B7: Burundi | C7: 3.2888887 | D7: 2.4 | E7: 3.5 | F7: 2.7013333 | G7: 13.238559 | H7: 230 | J7: =(F7^3)*(H7^-0.125)*G7 -> 132.2389 | L7: =IF(ISERROR(J7),"",J7/N7) -> 0.78644336 | N7: =O7-15 -> 168.14803 | O7: =VLOOKUP(B7,'Table 1'!$A$8:$G$99,7,FALSE) -> 183.14803
A8: BF | B8: Comoros | C8: 2.8555557 | D8: 2.1 | E8: 3.5 | F8: 2.3933334 | G8: 0.852075 | H8: 1600 | J8: =(F8^3)*(H8^-0.125)*G8 -> 4.6448576 | L8: =IF(ISERROR(J8),"",J8/N8) -> 1.4749585 | N8: =O8-15 -> 3.1491447 | O8: =VLOOKUP(B8,'Table 1'!$A$8:$G$99,7,FALSE) -> 18.149145
A9: BI | B9: Congo, Democratic Republic of | C9: 3.3666667 | D9: 2.6 | E9: 3.5 | F9: 2.856 | G9: 102.26281 | H9: 660 | J9: =(F9^3)*(H9^-0.125)*G9 -> 1058.1551 | L9: =IF(ISERROR(J9),"",J9/N9) -> 1.4749585 | N9: =O9-15 -> 717.41349 | O9: =VLOOKUP(B9,'Table 1'!$A$8:$G$99,7,FALSE) -> 732.41349
A10: CM | B10: Eritrea | C10: 1.7555557 | D10: 1.5 | E10: na | F10: 1.5817778 | G10: 3.748901 | H10: na | J10: =(F10^3)*(H10^-0.125)*G10 -> #VALUE! | L10: =IF(ISERROR(J10),"",J10/N10) | N10: =O10-15 -> -15 | O10: =VLOOKUP(B10,'Table 1'!$A$8:$G$99,7,FALSE) -> 0
B11: Eswatini | C11: na | D11: na | E11: na | F11: na | G11: 1.210822 | H11: 3860 | J11: =(F11^3)*(H11^-0.125)*G11 -> #VALUE! | L11: =IF(ISERROR(J11),"",J11/N11) | N11: =O11-15 -> 5.7951876 | O11: =VLOOKUP(B11,'Table 1'!$A$8:$G$99,7,FALSE) -> 20.795188
A12: CV | B12: Ethiopia | C12: 3.1666667 | D12: 3.1 | E12: 4 | F12: 3.188 | G12: 126.52706 | H12: 1130 | J12: =(F12^3)*(H12^-0.125)*G12 -> 1702.5644 | L12: =IF(ISERROR(J12),"",J12/N12) -> 1.4749585 | N12: =O12-15 -> 1154.3135 | O12: =VLOOKUP(B12,'Table 1'!$A$8:$G$99,7,FALSE) -> 1169.3135
A13: CF | B13: Kenya | C13: 3.911111 | D13: 3.6 | E13: 3 | F13: 3.6266666 | G13: 55.100586 | H13: 2110 | J13: =(F13^3)*(H13^-0.125)*G13 -> 1009.5872 | L13: =IF(ISERROR(J13),"",J13/N13) -> 1.4749585 | N13: =O13-15 -> 684.48515 | O13: =VLOOKUP(B13,'Table 1'!$A$8:$G$99,7,FALSE) -> 699.48515
A14: TD | B14: Lesotho | C14: 3.388889 | D14: 2.9 | E14: 3 | F14: 3.0253334 | G14: 2.330318 | H14: 1160 | J14: =(F14^3)*(H14^-0.125)*G14 -> 26.710231 | L14: =IF(ISERROR(J14),"",J14/N14) -> 1.4749585 | N14: =O14-15 -> 18.109141 | O14: =VLOOKUP(B14,'Table 1'!$A$8:$G$99,7,FALSE) -> 33.109141
A15: KM | B15: Madagascar | C15: 3.4333333 | D15: 2.7 | E15: 3.5 | F15: 2.94 | G15: 30.325732 | H15: 530 | J15: =(F15^3)*(H15^-0.125)*G15 -> 351.8186 | L15: =IF(ISERROR(J15),"",J15/N15) -> 1.4749585 | N15: =O15-15 -> 238.5278 | O15: =VLOOKUP(B15,'Table 1'!$A$8:$G$99,7,FALSE) -> 253.5278
A16: ZR | B16: Malawi | C16: 3.0333333 | D16: 3 | E16: 3.5 | F16: 3.048 | G16: 20.931751 | H16: 640 | J16: =(F16^3)*(H16^-0.125)*G16 -> 264.28831 | L16: =IF(ISERROR(J16),"",J16/N16) -> 1.4749585 | N16: =O16-15 -> 179.18356 | O16: =VLOOKUP(B16,'Table 1'!$A$8:$G$99,7,FALSE) -> 194.18356
A17: CG | B17: Mozambique | C17: 3.2111113 | D17: 2.9 | E17: 3 | F17: 2.9826667 | G17: 33.897354 | H17: 530 | J17: =(F17^3)*(H17^-0.125)*G17 -> 410.62511 | L17: =IF(ISERROR(J17),"",J17/N17) -> 0.92976652 | N17: =O17-15 -> 441.64325 | O17: =VLOOKUP(B17,'Table 1'!$A$8:$G$99,7,FALSE) -> 456.64325
A18: CI | B18: Rwanda | C18: 4.188889 | D18: 3.9 | E18: 3.5 | F18: 3.9373334 | G18: 14.094683 | H18: 980 | J18: =(F18^3)*(H18^-0.125)*G18 -> 363.71282 | L18: =IF(ISERROR(J18),"",J18/N18) -> 1.4749585 | N18: =O18-15 -> 246.59191 | O18: =VLOOKUP(B18,'Table 1'!$A$8:$G$99,7,FALSE) -> 261.59191
A19: ER | B19: Sao Tome and Principe | C19: 2.9 | D19: 3 | E19: 3.5 | F19: 3.016 | G19: 0.231856 | H19: 2480 | J19: =(F19^3)*(H19^-0.125)*G19 -> 2.3944507 | L19: =IF(ISERROR(J19),"",J19/N19) -> 1.4749585 | N19: =O19-15 -> 1.6234021 | O19: =VLOOKUP(B19,'Table 1'!$A$8:$G$99,7,FALSE) -> 16.623402
A20: ET | B20: Somalia | C20: 2.3333333 | D20: 1.9 | E20: 4 | F20: 2.172 | G20: 18.143378 | H20: 610 | J20: =(F20^3)*(H20^-0.125)*G20 -> 83.393343 | L20: =IF(ISERROR(J20),"",J20/N20) -> 0.39200038 | N20: =O20-15 -> 212.73791 | O20: =VLOOKUP(B20,'Table 1'!$A$8:$G$99,7,FALSE) -> 227.73791
A21: GM | B21: South Sudan | C21: 1.788889 | D21: 1.3 | E21: 3.5 | F21: 1.5933334 | G21: 11.088796 | H21: na | J21: =(F21^3)*(H21^-0.125)*G21 -> #VALUE! | L21: =IF(ISERROR(J21),"",J21/N21) | N21: =O21-15 -> 56.482788 | O21: =VLOOKUP(B21,'Table 1'!$A$8:$G$99,7,FALSE) -> 71.482788
A22: GH | B22: Sudan | C22: 2.0666667 | D22: 1.8 | E22: 4 | F22: 2.04 | G22: 48.109006 | H22: 990 | J22: =(F22^3)*(H22^-0.125)*G22 -> 172.44972 | L22: =IF(ISERROR(J22),"",J22/N22) -> 1.4749585 | N22: =O22-15 -> 116.91835 | O22: =VLOOKUP(B22,'Table 1'!$A$8:$G$99,7,FALSE) -> 131.91835
A23: GN | B23: Tanzania | C23: 3.6444447 | D23: 3.1 | E23: 3.5 | F23: 3.2626667 | G23: 65.36289 | H23: 1210 | J23: =(F23^3)*(H23^-0.125)*G23 -> 934.76235 | L23: =IF(ISERROR(J23),"",J23/N23) -> 1.4749585 | N23: =O23-15 -> 633.75504 | O23: =VLOOKUP(B23,'Table 1'!$A$8:$G$99,7,FALSE) -> 648.75504
A24: GW | B24: Uganda | C24: 3.6333333 | D24: 3.3 | E24: 3 | F24: 3.356 | G24: 48.582334 | H24: 980 | J24: =(F24^3)*(H24^-0.125)*G24 -> 776.32035 | L24: =IF(ISERROR(J24),"",J24/N24) -> 1.4749585 | N24: =O24-15 -> 526.3337 | O24: =VLOOKUP(B24,'Table 1'!$A$8:$G$99,7,FALSE) -> 541.3337
A25: KE | B25: Zambia | C25: 3.3555553 | D25: 2.9 | E25: 3.5 | F25: 3.0573333 | G25: 20.569737 | H25: 1320 | J25: =(F25^3)*(H25^-0.125)*G25 -> 239.43374 | L25: =IF(ISERROR(J25),"",J25/N25) -> 1.4749585 | N25: =O25-15 -> 162.33253 | O25: =VLOOKUP(B25,'Table 1'!$A$8:$G$99,7,FALSE) -> 177.33253
A26: LS | B26: Zimbabwe | C26: 3.011111 | D26: 2.9 | E26: 4.5 | F26: 3.0546666 | G26: 16.665409 | H26: 1740 | J26: =(F26^3)*(H26^-0.125)*G26 -> 186.91269 | L26: =IF(ISERROR(J26),"",J26/N26) -> -12.460846 | N26: =O26-15 -> -15 | O26: =VLOOKUP(B26,'Table 1'!$A$8:$G$99,7,FALSE) -> 0
B27: Africa Western and Central | J27: =(F27^3)*(H27^-0.125)*G27 -> #DIV/0! | L27: =IF(ISERROR(J27),"",J27/N27) | N27: =O27-15 -> -15 | O27: =VLOOKUP(B27,'Table 1'!$A$8:$G$99,7,FALSE) -> 0
A28: LR | B28: Benin | C28: 3.9666667 | D28: 3.7 | E28: 4 | F28: 3.788 | G28: 13.712828 | H28: 1440 | J28: =(F28^3)*(H28^-0.125)*G28 -> 300.30435 | L28: =IF(ISERROR(J28),"",J28/N28) -> 0.81860835 | N28: =O28-15 -> 366.84741 | O28: =VLOOKUP(B28,'Table 1'!$A$8:$G$99,7,FALSE) -> 381.84741
A29: MG | B29: Burkina Faso | C29: 3.5 | D29: 3.2 | E29: 3.5 | F29: 3.296 | G29: 23.251485 | H29: 850 | J29: =(F29^3)*(H29^-0.125)*G29 -> 358.29021 | L29: =IF(ISERROR(J29),"",J29/N29) -> 1.4749585 | N29: =O29-15 -> 242.91546 | O29: =VLOOKUP(B29,'Table 1'!$A$8:$G$99,7,FALSE) -> 257.91546
A30: MW | B30: Cameroon | C30: 3.4333333 | D30: 3 | E30: 3 | F30: 3.104 | G30: 28.647293 | H30: 1650 | J30: =(F30^3)*(H30^-0.125)*G30 -> 339.36202 | L30: =IF(ISERROR(J30),"",J30/N30) -> 1.4749585 | N30: =O30-15 -> 230.08242 | O30: =VLOOKUP(B30,'Table 1'!$A$8:$G$99,7,FALSE) -> 245.08242
A31: ML | B31: Cape Verde | C31: 3.8333333 | D31: 4 | E31: 3.5 | F31: 3.92 | G31: 0.598682 | H31: 4280 | J31: =(F31^3)*(H31^-0.125)*G31 -> 12.680137 | L31: =IF(ISERROR(J31),"",J31/N31) -> 1.4749585 | N31: =O31-15 -> 8.5969448 | O31: =VLOOKUP(B31,'Table 1'!$A$8:$G$99,7,FALSE) -> 23.596945
A32: MR | B32: Central African Republic | C32: 2.6555557 | D32: 2.4 | E32: 4 | F32: 2.5893334 | G32: 5.742315 | H32: 470 | J32: =(F32^3)*(H32^-0.125)*G32 -> 46.199649 | L32: =IF(ISERROR(J32),"",J32/N32) -> 1.4749585 | N32: =O32-15 -> 31.322678 | O32: =VLOOKUP(B32,'Table 1'!$A$8:$G$99,7,FALSE) -> 46.322678
A33: MZ | B33: Chad | C33: 2.8 | D33: 2.4 | E33: 3 | F33: 2.544 | G33: 18.278568 | H33: 710 | J33: =(F33^3)*(H33^-0.125)*G33 -> 132.46044 | L33: =IF(ISERROR(J33),"",J33/N33) -> 0.93144693 | N33: =O33-15 -> 142.20933 | O33: =VLOOKUP(B33,'Table 1'!$A$8:$G$99,7,FALSE) -> 157.20933
A34: NE | B34: Congo, Republic of | C34: 2.888889 | D34: 2.8 | E34: 3 | F34: 2.8373334 | G34: 6.106869 | H34: 2470 | J34: =(F34^3)*(H34^-0.125)*G34 -> 52.536674 | L34: =IF(ISERROR(J34),"",J34/N34) -> 1.4749585 | N34: =O34-15 -> 35.619087 | O34: =VLOOKUP(B34,'Table 1'!$A$8:$G$99,7,FALSE) -> 50.619087
A35: NG | B35: Cote d'Ivoire | C35: 3.8444443 | D35: 3.7 | E35: 3.5 | F35: 3.7186666 | G35: 28.873034 | H35: 2670 | J35: =(F35^3)*(H35^-0.125)*G35 -> 553.78381 | L35: =IF(ISERROR(J35),"",J35/N35) -> 1.4749585 | N35: =O35-15 -> 375.45723 | O35: =VLOOKUP(B35,'Table 1'!$A$8:$G$99,7,FALSE) -> 390.45723
A36: RW | B36: Gambia, The | C36: 3.1444447 | D36: 3.1 | E36: 3.5 | F36: 3.1426667 | G36: 2.773168 | H36: 830 | J36: =(F36^3)*(H36^-0.125)*G36 -> 37.152359 | L36: =IF(ISERROR(J36),"",J36/N36) -> 0.49257559 | N36: =O36-15 -> 75.424686 | O36: =VLOOKUP(B36,'Table 1'!$A$8:$G$99,7,FALSE) -> 90.424686
A37: ST | B37: Ghana | C37: 3.3444443 | D37: 3.6 | E37: 3.5 | F37: 3.5306666 | G37: 34.121985 | H37: 2340 | J37: =(F37^3)*(H37^-0.125)*G37 -> 569.44587 | L37: =IF(ISERROR(J37),"",J37/N37) -> 1.4749585 | N37: =O37-15 -> 386.07587 | O37: =VLOOKUP(B37,'Table 1'!$A$8:$G$99,7,FALSE) -> 401.07587
A38: SN | B38: Guinea | C38: 3.522222 | D38: 3 | E38: 2.5 | F38: 3.0853333 | G38: 14.190612 | H38: 1360 | J38: =(F38^3)*(H38^-0.125)*G38 -> 169.12781 | L38: =IF(ISERROR(J38),"",J38/N38) -> 1.4749585 | N38: =O38-15 -> 114.66615 | O38: =VLOOKUP(B38,'Table 1'!$A$8:$G$99,7,FALSE) -> 129.66615
A39: SL | B39: Guinea-Bissau | C39: 2.722222 | D39: 2.1 | E39: 3.5 | F39: 2.3613333 | G39: 2.150842 | H39: 900 | J39: =(F39^3)*(H39^-0.125)*G39 -> 12.100409 | L39: =IF(ISERROR(J39),"",J39/N39) -> 1.4749585 | N39: =O39-15 -> 8.2038983 | O39: =VLOOKUP(B39,'Table 1'!$A$8:$G$99,7,FALSE) -> 23.203898
... A47: ZW | B47: Togo | C47: 3.8888887 | D47: 3.4 | E47: 3.5 | F47: 3.5253333 | G47: 9.053799 | H47: 1030 | J47: =(F47^3)*(H47^-0.125)*G47 -> 166.65822 | L47: =IF(ISERROR(J47),"",J47/N47) -> 0.79746247 | N47: =O47-15 -> 208.98566 | O47: =VLOOKUP(B47,'Table 1'!$A$8:$G$99,7,FALSE) -> 223.98566
B48: East Asia and the Pacific | J48: =(F48^3)*(H48^-0.125)*G48 -> #DIV/0! | L48: =IF(ISERROR(J48),"",J48/N48) | N48: =O48-15 -> -15 | O48: =VLOOKUP(B48,'Table 1'!$A$8:$G$99,7,FALSE) -> 0
A49: KH | B49: Cambodia | C49: 3.8222223 | D49: 2.8 | E49: 3.5 | F49: 3.1013334 | G49: 16.944826 | H49: 1810 | J49: =(F49^3)*(H49^-0.125)*G49 -> 197.91224 | L49: =IF(ISERROR(J49),"",J49/N49) -> 1.4749585 | N49: =O49-15 -> 134.18157 | O49: =VLOOKUP(B49,'Table 1'!$A$8:$G$99,7,FALSE) -> 149.18157
...

Sheet forR
A1: country | B1: CPIA_ave_abc | C1: CPIA_D | D1: PPR | E1: CPR | F1: pop | G1: gnipc | H1: allocation
A2: Burundi | B2: 3.2888887 | C2: 2.4 | D2: 3.5 | E2: 2.7013333 | F2: 13.238559 | G2: 230 | H2: 183.14803
A3: Comoros | B3: 2.8555557 | C3: 2.1 | D3: 3.5 | E3: 2.3933334 | F3: 0.852075 | G3: 1600 | H3: 18.149145
A4: Congo, Democratic Republic of | B4: 3.3666667 | C4: 2.6 | D4: 3.5 | E4: 2.856 | F4: 102.26281 | G4: 660 | H4: 732.41349
A5: Eritrea | B5: 1.7555557 | C5: 1.5 | D5: na | E5: 1.5817778 | F5: 3.748901 | G5: na | H5: 0
A6: Eswatini | B6: na | C6: na | D6: na | E6: na | F6: 1.210822 | G6: 3860 | H6: 20.795188
A7: Ethiopia | B7: 3.1666667 | C7: 3.1 | D7: 4 | E7: 3.188 | F7: 126.52706 | G7: 1130 | H7: 1169.3135
A8: Kenya | B8: 3.911111 | C8: 3.6 | D8: 3 | E8: 3.6266666 | F8: 55.100586 | G8: 2110 | H8: 699.48515
A9: Lesotho | B9: 3.388889 | C9: 2.9 | D9: 3 | E9: 3.0253334 | F9: 2.330318 | G9: 1160 | H9: 33.109141
A10: Madagascar | B10: 3.4333333 | C10: 2.7 | D10: 3.5 | E10: 2.94 | F10: 30.325732 | G10: 530 | H10: 253.5278
A11: Malawi | B11: 3.0333333 | C11: 3 | D11: 3.5 | E11: 3.048 | F11: 20.931751 | G11: 640 | H11: 194.18356
A12: Mozambique | B12: 3.2111113 | C12: 2.9 | D12: 3 | E12: 2.9826667 | F12: 33.897354 | G12: 530 | H12: 456.64325
A13: Rwanda | B13: 4.188889 | C13: 3.9 | D13: 3.5 | E13: 3.9373334 | F13: 14.094683 | G13: 980 | H13: 261.59191
A14: Sao Tome and Principe | B14: 2.9 | C14: 3 | D14: 3.5 | E14: 3.016 | F14: 0.231856 | G14: 2480 | H14: 16.623402
A15: Somalia | B15: 2.3333333 | C15: 1.9 | D15: 4 | E15: 2.172 | F15: 18.143378 | G15: 610 | H15: 227.73791
A16: South Sudan | B16: 1.788889 | C16: 1.3 | D16: 3.5 | E16: 1.5933334 | F16: 11.088796 | G16: na | H16: 71.482788
A17: Sudan | B17: 2.0666667 | C17: 1.8 | D17: 4 | E17: 2.04 | F17: 48.109006 | G17: 990 | H17: 131.91835
A18: Tanzania | B18: 3.6444447 | C18: 3.1 | D18: 3.5 | E18: 3.2626667 | F18: 65.36289 | G18: 1210 | H18: 648.75504
A19: Uganda | B19: 3.6333333 | C19: 3.3 | D19: 3 | E19: 3.356 | F19: 48.582334 | G19: 980 | H19: 541.3337
A20: Zambia | B20: 3.3555553 | C20: 2.9 | D20: 3.5 | E20: 3.0573333 | F20: 20.569737 | G20: 1320 | H20: 177.33253
A21: Zimbabwe | B21: 3.011111 | C21: 2.9 | D21: 4.5 | E21: 3.0546666 | F21: 16.665409 | G21: 1740 | H21: 0
A22: Benin | B22: 3.9666667 | C22: 3.7 | D22: 4 | E22: 3.788 | F22: 13.712828 | G22: 1440 | H22: 381.84741
A23: Burkina Faso | B23: 3.5 | C23: 3.2 | D23: 3.5 | E23: 3.296 | F23: 23.251485 | G23: 850 | H23: 257.91546
A24: Cameroon | B24: 3.4333333 | C24: 3 | D24: 3 | E24: 3.104 | F24: 28.647293 | G24: 1650 | H24: 245.08242
A25: Cape Verde | B25: 3.8333333 | C25: 4 | D25: 3.5 | E25: 3.92 | F25: 0.598682 | G25: 4280 | H25: 23.596945
A26: Central African Republic | B26: 2.6555557 | C26: 2.4 | D26: 4 | E26: 2.5893334 | F26: 5.742315 | G26: 470 | H26: 46.322678
A27: Chad | B27: 2.8 | C27: 2.4 | D27: 3 | E27: 2.544 | F27: 18.278568 | G27: 710 | H27: 157.20933
A28: Congo, Republic of | B28: 2.888889 | C28: 2.8 | D28: 3 | E28: 2.8373334 | F28: 6.106869 | G28: 2470 | H28: 50.619087
... A52: Timor-Leste | B52: 2.8555553 | C52: 2.6 | D52: 2.5 | E52: 2.6533333 | F52: 1.360596 | G52: 2140 | H52: 21.607286
A53: Tonga | B53: 3.411111 | C53: 3.6 | D53: 2.5 | E53: 3.4666666 | F53: 0.107773 | G53: na | H53: 16.046155
A54: Tuvalu | B54: 2.7444447 | C54: 3.2 | D54: 3 | E54: 3.0746667 | F54: 0.011396 | G54: 7550 | H54: 15.073557
A55: Vanuatu | B55: 3.3666667 | C55: 3.1 | D55: 4 | E55: 3.236 | F55: 0.334506 | G55: 3660 | H55: 17.75559
A56: Kosovo | B56: 3.9111113 | C56: 3.5 | D56: 3.5 | E56: 3.5986667 | F56: 1.756374 | G56: 5980 | H56: 33.714337
A57: Kyrgyz Republic | B57: 3.7666667 | C57: 3 | D57: 3.5 | E57: 3.224 | F57: 7.1008 | G57: 1700 | H57: 78.66584
A58: Tajikistan | B58: 3.222222 | C58: 3.1 | D58: 3 | E58: 3.1213333 | F58: 10.143543 | G58: 1440 | H58: 99.262628
A59: Uzbekistan | B59: 3.888889 | C59: 3.7 | D59: 3 | E59: 3.6893334 | F59: 36.41235 | G59: 2360 | H59: 484.56813
A60: Belize | B60: na | C60: na | D60: na | E60: na | F60: 0.410825 | G60: 7190 | H60: 17.512578
A61: Dominica | B61: 3.6333333 | C61: 3.7 | D61: 3.5 | E61: 3.668 | F61: 0.07304 | G61: 8920 | H61: 15.783923
A62: Grenada | B62: 3.8 | C62: 3.5 | D62: 3.5 | E62: 3.572 | F62: 0.126183 | G62: 9800 | H62: 16.236096
A63: Guyana | B63: 3.3222223 | C63: 3.2 | D63: 3.5 | E63: 3.2533334 | F63: 0.813834 | G63: 20360 | H63: 20.497238
...
